<?xml version="1.0" ?>
<robot name="MiniHex">

<material name="silver">
  <color rgba="0.700 0.700 0.700 1.000"/>
</material>

<material name="red">
  <color rgba="1.000 0.000 0.000 1.000"/>
</material>

<material name="green">
  <color rgba="0.000 1.000 0.000 1.000"/>
</material>

<material name="blue">
  <color rgba="0.000 0.000 1.000 1.000"/>
</material>

<material name="yellow">
  <color rgba="1.000 0.900 0.000 1.000"/>
</material>

<link name="base_link">
  <inertial>
    <origin xyz="-2.5465707758764093e-16 -3.145863765132658e-13 0.0024101543695510897" rpy="0 0 0"/>
    <mass value="0.42053809047151236"/>
    <inertia ixx="0.00028254911235019707" iyy="0.00028226882743274896" izz="0.0005380720803144401" ixy="-7.139533408580586e-19" iyz="-1.2041830102324297e-16" ixz="-1.688664970194084e-19"/>
  </inertial>
  <visual>
    <origin xyz="0 0 0" rpy="0 0 0"/>
    <geometry>
      <mesh filename="meshes/base_link.stl" scale="0.001 0.001 0.001"/>
    </geometry>
    <material name="blue"/>
    <material/>
  </visual>
  <collision>
    <origin xyz="0 0 0" rpy="0 0 0"/>
    <geometry>
      <mesh filename="meshes/base_link.stl" scale="0.001 0.001 0.001"/>
    </geometry>
  </collision>
</link>

<link name="9g_servo_1A1">
  <inertial>
    <origin xyz="-0.014271299478847452 1.1511731251974464e-10 -0.0024958056337759894" rpy="0 0 0"/>
    <mass value="0.055054783503500355"/>
    <inertia ixx="3.4536923767764674e-06" iyy="5.269670254190792e-06" izz="3.20378515754883e-06" ixy="-1.573879877911482e-14" iyz="2.1462796422866795e-14" ixz="3.7937499037505966e-07"/>
  </inertial>
  <visual>
    <origin xyz="0.0185 -0.0 -0.01" rpy="0 0 0"/>
    <geometry>
      <mesh filename="meshes/9g_servo_1A1.stl" scale="0.001 0.001 0.001"/>
    </geometry>
    <material name="yellow"/>
    <material/>
  </visual>
  <collision>
    <origin xyz="0.0185 -0.0 -0.01" rpy="0 0 0"/>
    <geometry>
      <mesh filename="meshes/9g_servo_1A1.stl" scale="0.001 0.001 0.001"/>
    </geometry>
  </collision>
</link>

<link name="Hip_Mount_11">
  <inertial>
    <origin xyz="-0.015286152121437399 -0.0006288649548319852 -0.016324077864696748" rpy="0 0 0"/>
    <mass value="0.032534903343574804"/>
    <inertia ixx="1.0000836670587191e-05" iyy="1.217229322945846e-05" izz="2.5332634841258048e-06" ixy="-1.4004600538383113e-07" iyz="-6.056877241274784e-09" ixz="-2.635468996168281e-08"/>
  </inertial>
  <visual>
    <origin xyz="0.037558 -0.0 -0.024275" rpy="0 0 0"/>
    <geometry>
      <mesh filename="meshes/Hip_Mount_11.stl" scale="0.001 0.001 0.001"/>
    </geometry>
    <material name="red"/>
    <material/>
  </visual>
  <collision>
    <origin xyz="0.037558 -0.0 -0.024275" rpy="0 0 0"/>
    <geometry>
      <mesh filename="meshes/Hip_Mount_11.stl" scale="0.001 0.001 0.001"/>
    </geometry>
  </collision>
</link>

<link name="9g_servo_1B1">
  <inertial>
    <origin xyz="-0.0005051736542879826 0.0024957004185076253 -0.013240640785541866" rpy="0 0 0"/>
    <mass value="0.05505478350350033"/>
    <inertia ixx="5.269618000874426e-06" iyy="3.20393809208813e-06" izz="3.4538924084124894e-06" ixy="-5.516306298229137e-12" iyz="3.793636676912937e-07" ixz="2.7506613699550438e-11"/>
  </inertial>
  <visual>
    <origin xyz="0.06374 0.00425 -0.022044" rpy="0 0 0"/>
    <geometry>
      <mesh filename="meshes/9g_servo_1B1.stl" scale="0.001 0.001 0.001"/>
    </geometry>
    <material name="yellow"/>
    <material/>
  </visual>
  <collision>
    <origin xyz="0.06374 0.00425 -0.022044" rpy="0 0 0"/>
    <geometry>
      <mesh filename="meshes/9g_servo_1B1.stl" scale="0.001 0.001 0.001"/>
    </geometry>
  </collision>
</link>

<link name="Hex_Leg_Joint_11">
  <inertial>
    <origin xyz="-0.02279618097426557 0.018608847716086164 -0.0002798785329614483" rpy="0 0 0"/>
    <mass value="0.048136391007076396"/>
    <inertia ixx="1.1974987914456798e-05" iyy="8.125439311283905e-06" izz="1.3118820247000047e-05" ixy="8.188768866583927e-07" iyz="-4.1189558944753496e-10" ixz="3.5300690483670285e-09"/>
  </inertial>
  <visual>
    <origin xyz="0.063809 0.018525 -0.014054" rpy="0 0 0"/>
    <geometry>
      <mesh filename="meshes/Hex_Leg_Joint_11.stl" scale="0.001 0.001 0.001"/>
    </geometry>
    <material name="red"/>
    <material/>
  </visual>
  <collision>
    <origin xyz="0.063809 0.018525 -0.014054" rpy="0 0 0"/>
    <geometry>
      <mesh filename="meshes/Hex_Leg_Joint_11.stl" scale="0.001 0.001 0.001"/>
    </geometry>
  </collision>
</link>

<link name="9g_servo_1C1">
  <inertial>
    <origin xyz="-0.0005070476232626325 0.0025177012982494948 -0.01354802288656062" rpy="0 0 0"/>
    <mass value="0.055054783503500314"/>
    <inertia ixx="5.269623391652945e-06" iyy="3.2041982411880375e-06" izz="3.454147166738822e-06" ixy="-8.234379835842442e-12" iyz="-3.793617562696562e-07" ixz="6.460354033145915e-11"/>
  </inertial>
  <visual>
    <origin xyz="0.095986 0.004044 -0.027056" rpy="0 0 0"/>
    <geometry>
      <mesh filename="meshes/9g_servo_1C1.stl" scale="0.001 0.001 0.001"/>
    </geometry>
    <material name="yellow"/>
    <material/>
  </visual>
  <collision>
    <origin xyz="0.095986 0.004044 -0.027056" rpy="0 0 0"/>
    <geometry>
      <mesh filename="meshes/9g_servo_1C1.stl" scale="0.001 0.001 0.001"/>
    </geometry>
  </collision>
</link>

<link name="Hex_Leg_End_11">
  <inertial>
    <origin xyz="-0.034049190150787806 0.016026216123514167 -3.8583269864327085e-05" rpy="0 0 0"/>
    <mass value="0.04016569851390242"/>
    <inertia ixx="1.1474042664158023e-05" iyy="1.6364460028107236e-05" izz="2.7404615065756434e-05" ixy="-7.477551223559862e-10" iyz="1.5909132597507857e-13" ixz="5.053527686180376e-09"/>
  </inertial>
  <visual>
    <origin xyz="0.095804 0.018069 -0.008069" rpy="0 0 0"/>
    <geometry>
      <mesh filename="meshes/Hex_Leg_End_11.stl" scale="0.001 0.001 0.001"/>
    </geometry>
    <material name="green"/>
    <material/>
  </visual>
  <collision>
    <origin xyz="0.095804 0.018069 -0.008069" rpy="0 0 0"/>
    <geometry>
      <mesh filename="meshes/Hex_Leg_End_11.stl" scale="0.001 0.001 0.001"/>
    </geometry>
  </collision>
</link>

<link name="9g_servo_2A1">
  <inertial>
    <origin xyz="-0.007135655637466149 0.01235978828604464 -0.002495801992830637" rpy="0 0 0"/>
    <mass value="0.05505477172840249"/>
    <inertia ixx="4.815661309975585e-06" iyy="3.907681847545061e-06" izz="3.203766235917451e-06" ixy="7.863332915432041e-07" iyz="-3.285451459287048e-07" ixz="1.8968565597864854e-07"/>
  </inertial>
  <visual>
    <origin xyz="0.00925 -0.016021 -0.01" rpy="0 0 0"/>
    <geometry>
      <mesh filename="meshes/9g_servo_2A1.stl" scale="0.001 0.001 0.001"/>
    </geometry>
    <material name="yellow"/>
    <material/>
  </visual>
  <collision>
    <origin xyz="0.00925 -0.016021 -0.01" rpy="0 0 0"/>
    <geometry>
      <mesh filename="meshes/9g_servo_2A1.stl" scale="0.001 0.001 0.001"/>
    </geometry>
  </collision>
</link>

<link name="Hip_Mount_21">
  <inertial>
    <origin xyz="-0.008187689087174762 0.012923945701157583 -0.016324077865203526" rpy="0 0 0"/>
    <mass value="0.03253490334357478"/>
    <inertia ixx="1.150814569123448e-05" iyy="1.0664984208686909e-05" izz="2.5332634839972184e-06" ixy="1.0102912742709978e-06" iyz="1.979539219249969e-08" ixz="-1.8422754658143607e-08"/>
  </inertial>
  <visual>
    <origin xyz="0.018779 -0.032526 -0.024275" rpy="0 0 0"/>
    <geometry>
      <mesh filename="meshes/Hip_Mount_21.stl" scale="0.001 0.001 0.001"/>
    </geometry>
    <material name="red"/>
    <material/>
  </visual>
  <collision>
    <origin xyz="0.018779 -0.032526 -0.024275" rpy="0 0 0"/>
    <geometry>
      <mesh filename="meshes/Hip_Mount_21.stl" scale="0.001 0.001 0.001"/>
    </geometry>
  </collision>
</link>

<link name="9g_servo_2B1">
  <inertial>
    <origin xyz="0.001909169038870652 0.0016847749490938452 -0.013240651855446789" rpy="0 0 0"/>
    <mass value="0.055054783544440086"/>
    <inertia ixx="3.720443650770199e-06" iyy="4.753233623190468e-06" izz="3.4540165574080167e-06" ixy="-8.944045723033339e-07" iyz="1.8964152887652804e-07" ixz="3.2855822153123924e-07"/>
  </inertial>
  <visual>
    <origin xyz="0.035551 -0.053076 -0.022044" rpy="0 0 0"/>
    <geometry>
      <mesh filename="meshes/9g_servo_2B1.stl" scale="0.001 0.001 0.001"/>
    </geometry>
    <material name="yellow"/>
    <material/>
  </visual>
  <collision>
    <origin xyz="0.035551 -0.053076 -0.022044" rpy="0 0 0"/>
    <geometry>
      <mesh filename="meshes/9g_servo_2B1.stl" scale="0.001 0.001 0.001"/>
    </geometry>
  </collision>
</link>

<link name="Hex_Leg_Joint_21">
  <inertial>
    <origin xyz="0.004718023765293365 0.029047210680837467 -0.00027987853504113196" rpy="0 0 0"/>
    <mass value="0.04813639100707639"/>
    <inertia ixx="9.79699464849509e-06" iyy="1.0303432577245047e-05" izz="1.3118820247000373e-05" ixy="-2.0763418850543365e-06" iyz="-3.2630771138177582e-09" ixz="1.4083225705715694e-09"/>
  </inertial>
  <visual>
    <origin xyz="0.047948 -0.045997 -0.014054" rpy="0 0 0"/>
    <geometry>
      <mesh filename="meshes/Hex_Leg_Joint_21.stl" scale="0.001 0.001 0.001"/>
    </geometry>
    <material name="red"/>
    <material/>
  </visual>
  <collision>
    <origin xyz="0.047948 -0.045997 -0.014054" rpy="0 0 0"/>
    <geometry>
      <mesh filename="meshes/Hex_Leg_Joint_21.stl" scale="0.001 0.001 0.001"/>
    </geometry>
  </collision>
</link>

<link name="9g_servo_2C1">
  <inertial>
    <origin xyz="0.0019276166695239433 0.001697341300166133 -0.013548020971379414" rpy="0 0 0"/>
    <mass value="0.055054783555037665"/>
    <inertia ixx="3.7202519620292826e-06" iyy="4.753169228184038e-06" izz="3.4537519772458213e-06" ixy="-8.945302084741123e-07" iyz="-1.896908426815986e-07" ixz="-3.285384084808927e-07"/>
  </inertial>
  <visual>
    <origin xyz="0.051496 -0.081105 -0.027056" rpy="0 0 0"/>
    <geometry>
      <mesh filename="meshes/9g_servo_2C1.stl" scale="0.001 0.001 0.001"/>
    </geometry>
    <material name="yellow"/>
    <material/>
  </visual>
  <collision>
    <origin xyz="0.051496 -0.081105 -0.027056" rpy="0 0 0"/>
    <geometry>
      <mesh filename="meshes/9g_servo_2C1.stl" scale="0.001 0.001 0.001"/>
    </geometry>
  </collision>
</link>

<link name="Hex_Leg_End_21">
  <inertial>
    <origin xyz="-0.0031446978070062553 0.0375007694949408 -3.858327304499809e-05" rpy="0 0 0"/>
    <mass value="0.04016569851390239"/>
    <inertia ixx="1.5141208112188164e-05" iyy="1.2697294580077037e-05" izz="2.7404615065756868e-05" ixy="2.1179867137054186e-06" iyz="-4.37640347324532e-09" ixz="2.5269016933282757e-09"/>
  </inertial>
  <visual>
    <origin xyz="0.063551 -0.073934 -0.008069" rpy="0 0 0"/>
    <geometry>
      <mesh filename="meshes/Hex_Leg_End_21.stl" scale="0.001 0.001 0.001"/>
    </geometry>
    <material name="green"/>
    <material/>
  </visual>
  <collision>
    <origin xyz="0.063551 -0.073934 -0.008069" rpy="0 0 0"/>
    <geometry>
      <mesh filename="meshes/Hex_Leg_End_21.stl" scale="0.001 0.001 0.001"/>
    </geometry>
  </collision>
</link>

<link name="9g_servo_3A1">
  <inertial>
    <origin xyz="0.007135656031083909 0.012359788504810496 -0.002495801883656234" rpy="0 0 0"/>
    <mass value="0.05505477131119869"/>
    <inertia ixx="4.815660867631067e-06" iyy="3.907681655282897e-06" izz="3.2037656295469e-06" ixy="-7.863330136425903e-07" iyz="-3.28545062856289e-07" ixz="-1.8968555941381444e-07"/>
  </inertial>
  <visual>
    <origin xyz="-0.00925 -0.016021 -0.01" rpy="0 0 0"/>
    <geometry>
      <mesh filename="meshes/9g_servo_3A1.stl" scale="0.001 0.001 0.001"/>
    </geometry>
    <material name="yellow"/>
    <material/>
  </visual>
  <collision>
    <origin xyz="-0.00925 -0.016021 -0.01" rpy="0 0 0"/>
    <geometry>
      <mesh filename="meshes/9g_servo_3A1.stl" scale="0.001 0.001 0.001"/>
    </geometry>
  </collision>
</link>

<link name="Hip_Mount_31">
  <inertial>
    <origin xyz="0.007098463034262887 0.013552810655989574 -0.01632407786558164" rpy="0 0 0"/>
    <mass value="0.03253490334357481"/>
    <inertia ixx="1.1750712487964136e-05" iyy="1.0422417411965123e-05" izz="2.533263484003778e-06" ixy="-8.702452688871807e-07" iyz="2.5852269459370963e-08" ixz="7.93193534530894e-09"/>
  </inertial>
  <visual>
    <origin xyz="-0.018779 -0.032526 -0.024275" rpy="0 0 0"/>
    <geometry>
      <mesh filename="meshes/Hip_Mount_31.stl" scale="0.001 0.001 0.001"/>
    </geometry>
    <material name="red"/>
    <material/>
  </visual>
  <collision>
    <origin xyz="-0.018779 -0.032526 -0.024275" rpy="0 0 0"/>
    <geometry>
      <mesh filename="meshes/Hip_Mount_31.stl" scale="0.001 0.001 0.001"/>
    </geometry>
  </collision>
</link>

<link name="9g_servo_3B1">
  <inertial>
    <origin xyz="0.0024143350513842095 -0.0008108499730559715 -0.013240625385414075" rpy="0 0 0"/>
    <mass value="0.05505478355503765"/>
    <inertia ixx="3.7202289065960147e-06" iyy="4.753159110494176e-06" izz="3.453720150994226e-06" ixy="8.945448485450874e-07" iyz="-1.8968694850744107e-07" ixz="3.2854093252003857e-07"/>
  </inertial>
  <visual>
    <origin xyz="-0.028189 -0.057326 -0.022044" rpy="0 0 0"/>
    <geometry>
      <mesh filename="meshes/9g_servo_3B1.stl" scale="0.001 0.001 0.001"/>
    </geometry>
    <material name="yellow"/>
    <material/>
  </visual>
  <collision>
    <origin xyz="-0.028189 -0.057326 -0.022044" rpy="0 0 0"/>
    <geometry>
      <mesh filename="meshes/9g_servo_3B1.stl" scale="0.001 0.001 0.001"/>
    </geometry>
  </collision>
</link>

<link name="Hex_Leg_Joint_31">
  <inertial>
    <origin xyz="0.027514204739558942 0.010438362965465992 -0.00027987853366591604" rpy="0 0 0"/>
    <mass value="0.04813639100707643"/>
    <inertia ixx="8.378658275659155e-06" iyy="1.1721768950081782e-05" izz="1.3118820247000318e-05" ixy="1.2574649983962383e-06" iyz="-2.8511816858487696e-09" ixz="-2.121746607852286e-09"/>
  </inertial>
  <visual>
    <origin xyz="-0.015861 -0.064522 -0.014054" rpy="0 0 0"/>
    <geometry>
      <mesh filename="meshes/Hex_Leg_Joint_31.stl" scale="0.001 0.001 0.001"/>
    </geometry>
    <material name="red"/>
    <material/>
  </visual>
  <collision>
    <origin xyz="-0.015861 -0.064522 -0.014054" rpy="0 0 0"/>
    <geometry>
      <mesh filename="meshes/Hex_Leg_Joint_31.stl" scale="0.001 0.001 0.001"/>
    </geometry>
  </collision>
</link>

<link name="9g_servo_3C1">
  <inertial>
    <origin xyz="0.0024336894467891085 -0.0008204699730596648 -0.013548024268368623" rpy="0 0 0"/>
    <mass value="0.05505478354444006"/>
    <inertia ixx="3.7207830988136305e-06" iyy="4.7533267608861984e-06" izz="3.4544315791176696e-06" ixy="8.94236063099605e-07" iyz="1.895876346813877e-07" ixz="-3.2858574179222183e-07"/>
  </inertial>
  <visual>
    <origin xyz="-0.044491 -0.085149 -0.027056" rpy="0 0 0"/>
    <geometry>
      <mesh filename="meshes/9g_servo_3C1.stl" scale="0.001 0.001 0.001"/>
    </geometry>
    <material name="yellow"/>
    <material/>
  </visual>
  <collision>
    <origin xyz="-0.044491 -0.085149 -0.027056" rpy="0 0 0"/>
    <geometry>
      <mesh filename="meshes/9g_servo_3C1.stl" scale="0.001 0.001 0.001"/>
    </geometry>
  </collision>
</link>

<link name="Hex_Leg_End_31">
  <inertial>
    <origin xyz="0.0309034923437815 0.021473553371033238 -3.85832711958696e-05" rpy="0 0 0"/>
    <mass value="0.04016569851390234"/>
    <inertia ixx="1.5142503262051714e-05" iyy="1.269599943021338e-05" izz="2.7404615065756976e-05" ixy="-2.11723895858322e-06" iyz="-4.376562542773431e-09" ixz="-2.526625892959811e-09"/>
  </inertial>
  <visual>
    <origin xyz="-0.032254 -0.092004 -0.008069" rpy="0 0 0"/>
    <geometry>
      <mesh filename="meshes/Hex_Leg_End_31.stl" scale="0.001 0.001 0.001"/>
    </geometry>
    <material name="green"/>
    <material/>
  </visual>
  <collision>
    <origin xyz="-0.032254 -0.092004 -0.008069" rpy="0 0 0"/>
    <geometry>
      <mesh filename="meshes/Hex_Leg_End_31.stl" scale="0.001 0.001 0.001"/>
    </geometry>
  </collision>
</link>

<link name="9g_servo_4A1">
  <inertial>
    <origin xyz="0.014271299478847452 -1.1511730860065267e-10 -0.0024958056337759894" rpy="0 0 0"/>
    <mass value="0.05505478350350035"/>
    <inertia ixx="3.4536923767764704e-06" iyy="5.269670254190792e-06" izz="3.203785157548823e-06" ixy="-1.5738799330725996e-14" iyz="-2.1462796539908703e-14" ixz="-3.7937499037506136e-07"/>
  </inertial>
  <visual>
    <origin xyz="-0.0185 -0.0 -0.01" rpy="0 0 0"/>
    <geometry>
      <mesh filename="meshes/9g_servo_4A1.stl" scale="0.001 0.001 0.001"/>
    </geometry>
    <material name="yellow"/>
    <material/>
  </visual>
  <collision>
    <origin xyz="-0.0185 -0.0 -0.01" rpy="0 0 0"/>
    <geometry>
      <mesh filename="meshes/9g_servo_4A1.stl" scale="0.001 0.001 0.001"/>
    </geometry>
  </collision>
</link>

<link name="Hip_Mount_41">
  <inertial>
    <origin xyz="0.015286152121437399 0.0006288649548319897 -0.016324077864696748" rpy="0 0 0"/>
    <mass value="0.0325349033435748"/>
    <inertia ixx="1.000083667058719e-05" iyy="1.2172293229458406e-05" izz="2.533263484125764e-06" ixy="-1.4004600538383367e-07" iyz="6.056877241272084e-09" ixz="2.6354689961664176e-08"/>
  </inertial>
  <visual>
    <origin xyz="-0.037558 0.0 -0.024275" rpy="0 0 0"/>
    <geometry>
      <mesh filename="meshes/Hip_Mount_41.stl" scale="0.001 0.001 0.001"/>
    </geometry>
    <material name="red"/>
    <material/>
  </visual>
  <collision>
    <origin xyz="-0.037558 0.0 -0.024275" rpy="0 0 0"/>
    <geometry>
      <mesh filename="meshes/Hip_Mount_41.stl" scale="0.001 0.001 0.001"/>
    </geometry>
  </collision>
</link>

<link name="9g_servo_4B1">
  <inertial>
    <origin xyz="0.0005051736542879826 -0.0024957004185076153 -0.013240640785541866" rpy="0 0 0"/>
    <mass value="0.055054783503500335"/>
    <inertia ixx="5.269618000874433e-06" iyy="3.2039380920882384e-06" izz="3.453892408412598e-06" ixy="-5.5163063050054e-12" iyz="-3.7936366769129487e-07" ixz="-2.7506613699550438e-11"/>
  </inertial>
  <visual>
    <origin xyz="-0.06374 -0.00425 -0.022044" rpy="0 0 0"/>
    <geometry>
      <mesh filename="meshes/9g_servo_4B1.stl" scale="0.001 0.001 0.001"/>
    </geometry>
    <material name="yellow"/>
    <material/>
  </visual>
  <collision>
    <origin xyz="-0.06374 -0.00425 -0.022044" rpy="0 0 0"/>
    <geometry>
      <mesh filename="meshes/9g_servo_4B1.stl" scale="0.001 0.001 0.001"/>
    </geometry>
  </collision>
</link>

<link name="Hex_Leg_Joint_41">
  <inertial>
    <origin xyz="0.022796180974265584 -0.01860884771608615 -0.00027987853296145525" rpy="0 0 0"/>
    <mass value="0.0481363910070764"/>
    <inertia ixx="1.1974987914456777e-05" iyy="8.12543931128396e-06" izz="1.3118820247000047e-05" ixy="8.188768866583808e-07" iyz="4.11895589441791e-10" ixz="-3.530069048380581e-09"/>
  </inertial>
  <visual>
    <origin xyz="-0.063809 -0.018525 -0.014054" rpy="0 0 0"/>
    <geometry>
      <mesh filename="meshes/Hex_Leg_Joint_41.stl" scale="0.001 0.001 0.001"/>
    </geometry>
    <material name="red"/>
    <material/>
  </visual>
  <collision>
    <origin xyz="-0.063809 -0.018525 -0.014054" rpy="0 0 0"/>
    <geometry>
      <mesh filename="meshes/Hex_Leg_Joint_41.stl" scale="0.001 0.001 0.001"/>
    </geometry>
  </collision>
</link>

<link name="9g_servo_4C1">
  <inertial>
    <origin xyz="0.0005070476232626464 -0.002517701298249484 -0.013548022886560625" rpy="0 0 0"/>
    <mass value="0.055054783503500314"/>
    <inertia ixx="5.26962339165295e-06" iyy="3.204198241187929e-06" izz="3.454147166738822e-06" ixy="-8.234379834148376e-12" iyz="3.7936175626965505e-07" ixz="-6.460354031790662e-11"/>
  </inertial>
  <visual>
    <origin xyz="-0.095986 -0.004044 -0.027056" rpy="0 0 0"/>
    <geometry>
      <mesh filename="meshes/9g_servo_4C1.stl" scale="0.001 0.001 0.001"/>
    </geometry>
    <material name="yellow"/>
    <material/>
  </visual>
  <collision>
    <origin xyz="-0.095986 -0.004044 -0.027056" rpy="0 0 0"/>
    <geometry>
      <mesh filename="meshes/9g_servo_4C1.stl" scale="0.001 0.001 0.001"/>
    </geometry>
  </collision>
</link>

<link name="Hex_Leg_End_41">
  <inertial>
    <origin xyz="0.034049190150787806 -0.016026216123514143 -3.8583269864323616e-05" rpy="0 0 0"/>
    <mass value="0.04016569851390242"/>
    <inertia ixx="1.1474042664158043e-05" iyy="1.6364460028107236e-05" izz="2.740461506575665e-05" ixy="-7.477551223881735e-10" iyz="-1.5909132205755119e-13" ixz="-5.053527686166824e-09"/>
  </inertial>
  <visual>
    <origin xyz="-0.095804 -0.018069 -0.008069" rpy="0 0 0"/>
    <geometry>
      <mesh filename="meshes/Hex_Leg_End_41.stl" scale="0.001 0.001 0.001"/>
    </geometry>
    <material name="green"/>
    <material/>
  </visual>
  <collision>
    <origin xyz="-0.095804 -0.018069 -0.008069" rpy="0 0 0"/>
    <geometry>
      <mesh filename="meshes/Hex_Leg_End_41.stl" scale="0.001 0.001 0.001"/>
    </geometry>
  </collision>
</link>

<link name="9g_servo_5A1">
  <inertial>
    <origin xyz="0.007135655637466156 -0.012359788286044626 -0.002495801992830635" rpy="0 0 0"/>
    <mass value="0.05505477172840251"/>
    <inertia ixx="4.815661309975605e-06" iyy="3.907681847545061e-06" izz="3.203766235917485e-06" ixy="7.863332915432109e-07" iyz="3.285451459287065e-07" ixz="-1.8968565597864685e-07"/>
  </inertial>
  <visual>
    <origin xyz="-0.00925 0.016021 -0.01" rpy="0 0 0"/>
    <geometry>
      <mesh filename="meshes/9g_servo_5A1.stl" scale="0.001 0.001 0.001"/>
    </geometry>
    <material name="yellow"/>
    <material/>
  </visual>
  <collision>
    <origin xyz="-0.00925 0.016021 -0.01" rpy="0 0 0"/>
    <geometry>
      <mesh filename="meshes/9g_servo_5A1.stl" scale="0.001 0.001 0.001"/>
    </geometry>
  </collision>
</link>

<link name="Hip_Mount_51">
  <inertial>
    <origin xyz="0.008187689087174762 -0.012923945701157548 -0.016324077865203512" rpy="0 0 0"/>
    <mass value="0.0325349033435748"/>
    <inertia ixx="1.1508145691241906e-05" iyy="1.0664984208686672e-05" izz="2.533263484004889e-06" ixy="1.010291274271025e-06" iyz="-1.979539219247428e-08" ixz="1.842275465814615e-08"/>
  </inertial>
  <visual>
    <origin xyz="-0.018779 0.032526 -0.024275" rpy="0 0 0"/>
    <geometry>
      <mesh filename="meshes/Hip_Mount_51.stl" scale="0.001 0.001 0.001"/>
    </geometry>
    <material name="red"/>
    <material/>
  </visual>
  <collision>
    <origin xyz="-0.018779 0.032526 -0.024275" rpy="0 0 0"/>
    <geometry>
      <mesh filename="meshes/Hip_Mount_51.stl" scale="0.001 0.001 0.001"/>
    </geometry>
  </collision>
</link>

<link name="9g_servo_5B1">
  <inertial>
    <origin xyz="-0.001909169038870638 -0.0016847749490938313 -0.013240651855446796" rpy="0 0 0"/>
    <mass value="0.05505478354444008"/>
    <inertia ixx="3.7204436507702534e-06" iyy="4.753233623190468e-06" izz="3.454016557408315e-06" ixy="-8.944045723033203e-07" iyz="-1.8964152887652804e-07" ixz="-3.2855822153124263e-07"/>
  </inertial>
  <visual>
    <origin xyz="-0.035551 0.053076 -0.022044" rpy="0 0 0"/>
    <geometry>
      <mesh filename="meshes/9g_servo_5B1.stl" scale="0.001 0.001 0.001"/>
    </geometry>
    <material name="yellow"/>
    <material/>
  </visual>
  <collision>
    <origin xyz="-0.035551 0.053076 -0.022044" rpy="0 0 0"/>
    <geometry>
      <mesh filename="meshes/9g_servo_5B1.stl" scale="0.001 0.001 0.001"/>
    </geometry>
  </collision>
</link>

<link name="Hex_Leg_Joint_51">
  <inertial>
    <origin xyz="-0.004718023765293365 -0.02904721068083748 -0.0002798785350411545" rpy="0 0 0"/>
    <mass value="0.048136391007076416"/>
    <inertia ixx="9.796994648495036e-06" iyy="1.0303432577245142e-05" izz="1.3118820247000427e-05" ixy="-2.0763418850544178e-06" iyz="3.2630771137771007e-09" ixz="-1.408322570585122e-09"/>
  </inertial>
  <visual>
    <origin xyz="-0.047948 0.045997 -0.014054" rpy="0 0 0"/>
    <geometry>
      <mesh filename="meshes/Hex_Leg_Joint_51.stl" scale="0.001 0.001 0.001"/>
    </geometry>
    <material name="red"/>
    <material/>
  </visual>
  <collision>
    <origin xyz="-0.047948 0.045997 -0.014054" rpy="0 0 0"/>
    <geometry>
      <mesh filename="meshes/Hex_Leg_Joint_51.stl" scale="0.001 0.001 0.001"/>
    </geometry>
  </collision>
</link>

<link name="9g_servo_5C1">
  <inertial>
    <origin xyz="-0.0019276166695239086 -0.0016973413001660775 -0.013548020971379441" rpy="0 0 0"/>
    <mass value="0.055054783555037665"/>
    <inertia ixx="3.7202519620293368e-06" iyy="4.7531692281839834e-06" izz="3.4537519772456044e-06" ixy="-8.945302084741394e-07" iyz="1.8969084268158506e-07" ixz="3.28538408480913e-07"/>
  </inertial>
  <visual>
    <origin xyz="-0.051496 0.081105 -0.027056" rpy="0 0 0"/>
    <geometry>
      <mesh filename="meshes/9g_servo_5C1.stl" scale="0.001 0.001 0.001"/>
    </geometry>
    <material name="yellow"/>
    <material/>
  </visual>
  <collision>
    <origin xyz="-0.051496 0.081105 -0.027056" rpy="0 0 0"/>
    <geometry>
      <mesh filename="meshes/9g_servo_5C1.stl" scale="0.001 0.001 0.001"/>
    </geometry>
  </collision>
</link>

<link name="Hex_Leg_End_51">
  <inertial>
    <origin xyz="0.003144697807006311 -0.03750076949494069 -3.8583273045036254e-05" rpy="0 0 0"/>
    <mass value="0.04016569851390242"/>
    <inertia ixx="1.514120811218838e-05" iyy="1.2697294580076956e-05" izz="2.7404615065757193e-05" ixy="2.1179867137055813e-06" iyz="4.376403473252096e-09" ixz="-2.526901693331664e-09"/>
  </inertial>
  <visual>
    <origin xyz="-0.063551 0.073934 -0.008069" rpy="0 0 0"/>
    <geometry>
      <mesh filename="meshes/Hex_Leg_End_51.stl" scale="0.001 0.001 0.001"/>
    </geometry>
    <material name="green"/>
    <material/>
  </visual>
  <collision>
    <origin xyz="-0.063551 0.073934 -0.008069" rpy="0 0 0"/>
    <geometry>
      <mesh filename="meshes/Hex_Leg_End_51.stl" scale="0.001 0.001 0.001"/>
    </geometry>
  </collision>
</link>

<link name="9g_servo_6A1">
  <inertial>
    <origin xyz="-0.007135656031083905 -0.012359788504810489 -0.002495801883656238" rpy="0 0 0"/>
    <mass value="0.055054771311198666"/>
    <inertia ixx="4.815660867631073e-06" iyy="3.907681655282904e-06" izz="3.2037656295469066e-06" ixy="-7.863330136425971e-07" iyz="3.2854506285629916e-07" ixz="1.8968555941381444e-07"/>
  </inertial>
  <visual>
    <origin xyz="0.00925 0.016021 -0.01" rpy="0 0 0"/>
    <geometry>
      <mesh filename="meshes/9g_servo_6A1.stl" scale="0.001 0.001 0.001"/>
    </geometry>
    <material name="yellow"/>
    <material/>
  </visual>
  <collision>
    <origin xyz="0.00925 0.016021 -0.01" rpy="0 0 0"/>
    <geometry>
      <mesh filename="meshes/9g_servo_6A1.stl" scale="0.001 0.001 0.001"/>
    </geometry>
  </collision>
</link>

<link name="Hip_Mount_61">
  <inertial>
    <origin xyz="-0.0070984630342628904 -0.013552810655989615 -0.016324077865581644" rpy="0 0 0"/>
    <mass value="0.03253490334357479"/>
    <inertia ixx="1.1750712487958254e-05" iyy="1.042241741196533e-05" izz="2.5332634839977063e-06" ixy="-8.70245268887201e-07" iyz="-2.5852269459379434e-08" ixz="-7.93193534530894e-09"/>
  </inertial>
  <visual>
    <origin xyz="0.018779 0.032526 -0.024275" rpy="0 0 0"/>
    <geometry>
      <mesh filename="meshes/Hip_Mount_61.stl" scale="0.001 0.001 0.001"/>
    </geometry>
    <material name="red"/>
    <material/>
  </visual>
  <collision>
    <origin xyz="0.018779 0.032526 -0.024275" rpy="0 0 0"/>
    <geometry>
      <mesh filename="meshes/Hip_Mount_61.stl" scale="0.001 0.001 0.001"/>
    </geometry>
  </collision>
</link>

<link name="9g_servo_6B1">
  <inertial>
    <origin xyz="-0.0024143350513842303 0.0008108499730559854 -0.013240625385414076" rpy="0 0 0"/>
    <mass value="0.055054783555037685"/>
    <inertia ixx="3.7202289065961503e-06" iyy="4.753159110494169e-06" izz="3.4537201509945244e-06" ixy="8.945448485450332e-07" iyz="1.8968694850744107e-07" ixz="-3.2854093252004874e-07"/>
  </inertial>
  <visual>
    <origin xyz="0.028189 0.057326 -0.022044" rpy="0 0 0"/>
    <geometry>
      <mesh filename="meshes/9g_servo_6B1.stl" scale="0.001 0.001 0.001"/>
    </geometry>
    <material name="yellow"/>
    <material/>
  </visual>
  <collision>
    <origin xyz="0.028189 0.057326 -0.022044" rpy="0 0 0"/>
    <geometry>
      <mesh filename="meshes/9g_servo_6B1.stl" scale="0.001 0.001 0.001"/>
    </geometry>
  </collision>
</link>

<link name="Hex_Leg_Joint_61">
  <inertial>
    <origin xyz="-0.02751420473955897 -0.010438362965465992 -0.00027987853366590737" rpy="0 0 0"/>
    <mass value="0.048136391007076416"/>
    <inertia ixx="8.378658275658992e-06" iyy="1.1721768950081715e-05" izz="1.3118820246999939e-05" ixy="1.2574649983962112e-06" iyz="2.8511816858216646e-09" ixz="2.121746607825181e-09"/>
  </inertial>
  <visual>
    <origin xyz="0.015861 0.064522 -0.014054" rpy="0 0 0"/>
    <geometry>
      <mesh filename="meshes/Hex_Leg_Joint_61.stl" scale="0.001 0.001 0.001"/>
    </geometry>
    <material name="red"/>
    <material/>
  </visual>
  <collision>
    <origin xyz="0.015861 0.064522 -0.014054" rpy="0 0 0"/>
    <geometry>
      <mesh filename="meshes/Hex_Leg_Joint_61.stl" scale="0.001 0.001 0.001"/>
    </geometry>
  </collision>
</link>

<link name="9g_servo_6C1">
  <inertial>
    <origin xyz="-0.0024336894467891224 0.0008204699730596926 -0.013548024268368628" rpy="0 0 0"/>
    <mass value="0.055054783544440045"/>
    <inertia ixx="3.7207830988135763e-06" iyy="4.753326760886253e-06" izz="3.4544315791173444e-06" ixy="8.94236063099605e-07" iyz="-1.8958763468137415e-07" ixz="3.2858574179224216e-07"/>
  </inertial>
  <visual>
    <origin xyz="0.044491 0.085149 -0.027056" rpy="0 0 0"/>
    <geometry>
      <mesh filename="meshes/9g_servo_6C1.stl" scale="0.001 0.001 0.001"/>
    </geometry>
    <material name="yellow"/>
    <material/>
  </visual>
  <collision>
    <origin xyz="0.044491 0.085149 -0.027056" rpy="0 0 0"/>
    <geometry>
      <mesh filename="meshes/9g_servo_6C1.stl" scale="0.001 0.001 0.001"/>
    </geometry>
  </collision>
</link>

<link name="Hex_Leg_End_61">
  <inertial>
    <origin xyz="-0.030903492343781543 -0.021473553371033183 -3.858327119588521e-05" rpy="0 0 0"/>
    <mass value="0.04016569851390237"/>
    <inertia ixx="1.514250326205193e-05" iyy="1.2695999430213406e-05" izz="2.740461506575741e-05" ixy="-2.1172389585832744e-06" iyz="4.376562542773431e-09" ixz="2.5266258929665874e-09"/>
  </inertial>
  <visual>
    <origin xyz="0.032254 0.092004 -0.008069" rpy="0 0 0"/>
    <geometry>
      <mesh filename="meshes/Hex_Leg_End_61.stl" scale="0.001 0.001 0.001"/>
    </geometry>
    <material name="green"/>
    <material/>
  </visual>
  <collision>
    <origin xyz="0.032254 0.092004 -0.008069" rpy="0 0 0"/>
    <geometry>
      <mesh filename="meshes/Hex_Leg_End_61.stl" scale="0.001 0.001 0.001"/>
    </geometry>
  </collision>
</link>

<joint name="Rigid_1" type="fixed">
  <origin xyz="-0.0185 0.0 0.01" rpy="0 0 0"/>
  <parent link="base_link"/>
  <child link="9g_servo_1A1"/>
</joint>

<joint name="Revolute_2" type="continuous">
  <origin xyz="-0.019058 0.0 0.014275" rpy="0 0 0"/>
  <parent link="9g_servo_1A1"/>
  <child link="Hip_Mount_11"/>
  <axis xyz="0.0 -0.0 1.0"/>
  <dynamics damping="0.0" friction="1.0"/>
</joint>
<transmission name="Revolute_2_tran">
  <type>transmission_interface/SimpleTransmission</type>
  <joint name="Revolute_2">
    <hardwareInterface>PositionJointInterface</hardwareInterface>
  </joint>
  <actuator name="Revolute_2_actr">
    <hardwareInterface>PositionJointInterface</hardwareInterface>
    <mechanicalReduction>1</mechanicalReduction>
  </actuator>
</transmission>

<joint name="Rigid_3" type="fixed">
  <origin xyz="-0.026182 -0.00425 -0.002231" rpy="0 0 0"/>
  <parent link="Hip_Mount_11"/>
  <child link="9g_servo_1B1"/>
</joint>

<joint name="Revolute_4" type="continuous">
  <origin xyz="-6.9e-05 -0.014275 -0.00799" rpy="0 0 0"/>
  <parent link="9g_servo_1B1"/>
  <child link="Hex_Leg_Joint_11"/>
  <axis xyz="-0.0 -1.0 0.0"/>
  <dynamics damping="0.0" friction="1.0"/>
</joint>
<transmission name="Revolute_4_tran">
  <type>transmission_interface/SimpleTransmission</type>
  <joint name="Revolute_4">
    <hardwareInterface>PositionJointInterface</hardwareInterface>
  </joint>
  <actuator name="Revolute_4_actr">
    <hardwareInterface>PositionJointInterface</hardwareInterface>
    <mechanicalReduction>1</mechanicalReduction>
  </actuator>
</transmission>

<joint name="Rigid_5" type="fixed">
  <origin xyz="-0.032177 0.014481 0.013002" rpy="0 0 0"/>
  <parent link="Hex_Leg_Joint_11"/>
  <child link="9g_servo_1C1"/>
</joint>

<joint name="Revolute_6" type="continuous">
  <origin xyz="0.000182 -0.014025 -0.018987" rpy="0 0 0"/>
  <parent link="9g_servo_1C1"/>
  <child link="Hex_Leg_End_11"/>
  <axis xyz="0.0 -1.0 -0.0"/>
  <dynamics damping="0.0" friction="1.0"/>
</joint>
<transmission name="Revolute_6_tran">
  <type>transmission_interface/SimpleTransmission</type>
  <joint name="Revolute_6">
    <hardwareInterface>PositionJointInterface</hardwareInterface>
  </joint>
  <actuator name="Revolute_6_actr">
    <hardwareInterface>PositionJointInterface</hardwareInterface>
    <mechanicalReduction>1</mechanicalReduction>
  </actuator>
</transmission>

<joint name="Rigid_7" type="fixed">
  <origin xyz="-0.00925 0.016021 0.01" rpy="0 0 0"/>
  <parent link="base_link"/>
  <child link="9g_servo_2A1"/>
</joint>

<joint name="Revolute_8" type="continuous">
  <origin xyz="-0.009529 0.016505 0.014275" rpy="0 0 0"/>
  <parent link="9g_servo_2A1"/>
  <child link="Hip_Mount_21"/>
  <axis xyz="-0.0 0.0 1.0"/>
  <dynamics damping="0.0" friction="1.0"/>
</joint>
<transmission name="Revolute_8_tran">
  <type>transmission_interface/SimpleTransmission</type>
  <joint name="Revolute_8">
    <hardwareInterface>PositionJointInterface</hardwareInterface>
  </joint>
  <actuator name="Revolute_8_actr">
    <hardwareInterface>PositionJointInterface</hardwareInterface>
    <mechanicalReduction>1</mechanicalReduction>
  </actuator>
</transmission>

<joint name="Rigid_9" type="fixed">
  <origin xyz="-0.016772 0.02055 -0.002231" rpy="0 0 0"/>
  <parent link="Hip_Mount_21"/>
  <child link="9g_servo_2B1"/>
</joint>

<joint name="Revolute_10" type="continuous">
  <origin xyz="-0.012397 -0.007079 -0.00799" rpy="0 0 0"/>
  <parent link="9g_servo_2B1"/>
  <child link="Hex_Leg_Joint_21"/>
  <axis xyz="-0.866025 -0.5 0.0"/>
  <dynamics damping="0.0" friction="1.0"/>
</joint>
<transmission name="Revolute_10_tran">
  <type>transmission_interface/SimpleTransmission</type>
  <joint name="Revolute_10">
    <hardwareInterface>PositionJointInterface</hardwareInterface>
  </joint>
  <actuator name="Revolute_10_actr">
    <hardwareInterface>PositionJointInterface</hardwareInterface>
    <mechanicalReduction>1</mechanicalReduction>
  </actuator>
</transmission>

<joint name="Rigid_11" type="fixed">
  <origin xyz="-0.003548 0.035108 0.013002" rpy="0 0 0"/>
  <parent link="Hex_Leg_Joint_21"/>
  <child link="9g_servo_2C1"/>
</joint>

<joint name="Revolute_12" type="continuous">
  <origin xyz="-0.012055 -0.007171 -0.018987" rpy="0 0 0"/>
  <parent link="9g_servo_2C1"/>
  <child link="Hex_Leg_End_21"/>
  <axis xyz="-0.866025 -0.5 0.0"/>
  <dynamics damping="0.0" friction="1.0"/>
</joint>
<transmission name="Revolute_12_tran">
  <type>transmission_interface/SimpleTransmission</type>
  <joint name="Revolute_12">
    <hardwareInterface>PositionJointInterface</hardwareInterface>
  </joint>
  <actuator name="Revolute_12_actr">
    <hardwareInterface>PositionJointInterface</hardwareInterface>
    <mechanicalReduction>1</mechanicalReduction>
  </actuator>
</transmission>

<joint name="Rigid_13" type="fixed">
  <origin xyz="0.00925 0.016021 0.01" rpy="0 0 0"/>
  <parent link="base_link"/>
  <child link="9g_servo_3A1"/>
</joint>

<joint name="Revolute_14" type="continuous">
  <origin xyz="0.009529 0.016505 0.014275" rpy="0 0 0"/>
  <parent link="9g_servo_3A1"/>
  <child link="Hip_Mount_31"/>
  <axis xyz="-0.0 0.0 1.0"/>
  <dynamics damping="0.0" friction="1.0"/>
</joint>
<transmission name="Revolute_14_tran">
  <type>transmission_interface/SimpleTransmission</type>
  <joint name="Revolute_14">
    <hardwareInterface>PositionJointInterface</hardwareInterface>
  </joint>
  <actuator name="Revolute_14_actr">
    <hardwareInterface>PositionJointInterface</hardwareInterface>
    <mechanicalReduction>1</mechanicalReduction>
  </actuator>
</transmission>

<joint name="Rigid_15" type="fixed">
  <origin xyz="0.00941 0.0248 -0.002231" rpy="0 0 0"/>
  <parent link="Hip_Mount_31"/>
  <child link="9g_servo_3B1"/>
</joint>

<joint name="Revolute_16" type="continuous">
  <origin xyz="-0.012328 0.007196 -0.00799" rpy="0 0 0"/>
  <parent link="9g_servo_3B1"/>
  <child link="Hex_Leg_Joint_31"/>
  <axis xyz="-0.866025 0.5 0.0"/>
  <dynamics damping="0.0" friction="1.0"/>
</joint>
<transmission name="Revolute_16_tran">
  <type>transmission_interface/SimpleTransmission</type>
  <joint name="Revolute_16">
    <hardwareInterface>PositionJointInterface</hardwareInterface>
  </joint>
  <actuator name="Revolute_16_actr">
    <hardwareInterface>PositionJointInterface</hardwareInterface>
    <mechanicalReduction>1</mechanicalReduction>
  </actuator>
</transmission>

<joint name="Rigid_17" type="fixed">
  <origin xyz="0.02863 0.020627 0.013002" rpy="0 0 0"/>
  <parent link="Hex_Leg_Joint_31"/>
  <child link="9g_servo_3C1"/>
</joint>

<joint name="Revolute_18" type="continuous">
  <origin xyz="-0.012237 0.006855 -0.018987" rpy="0 0 0"/>
  <parent link="9g_servo_3C1"/>
  <child link="Hex_Leg_End_31"/>
  <axis xyz="-0.866025 0.5 -0.0"/>
  <dynamics damping="0.0" friction="1.0"/>
</joint>
<transmission name="Revolute_18_tran">
  <type>transmission_interface/SimpleTransmission</type>
  <joint name="Revolute_18">
    <hardwareInterface>PositionJointInterface</hardwareInterface>
  </joint>
  <actuator name="Revolute_18_actr">
    <hardwareInterface>PositionJointInterface</hardwareInterface>
    <mechanicalReduction>1</mechanicalReduction>
  </actuator>
</transmission>

<joint name="Rigid_19" type="fixed">
  <origin xyz="0.0185 0.0 0.01" rpy="0 0 0"/>
  <parent link="base_link"/>
  <child link="9g_servo_4A1"/>
</joint>

<joint name="Revolute_20" type="continuous">
  <origin xyz="0.019058 -0.0 0.014275" rpy="0 0 0"/>
  <parent link="9g_servo_4A1"/>
  <child link="Hip_Mount_41"/>
  <axis xyz="-0.0 -0.0 -1.0"/>
  <dynamics damping="0.0" friction="1.0"/>
</joint>
<transmission name="Revolute_20_tran">
  <type>transmission_interface/SimpleTransmission</type>
  <joint name="Revolute_20">
    <hardwareInterface>PositionJointInterface</hardwareInterface>
  </joint>
  <actuator name="Revolute_20_actr">
    <hardwareInterface>PositionJointInterface</hardwareInterface>
    <mechanicalReduction>1</mechanicalReduction>
  </actuator>
</transmission>

<joint name="Rigid_21" type="fixed">
  <origin xyz="0.026182 0.00425 -0.002231" rpy="0 0 0"/>
  <parent link="Hip_Mount_41"/>
  <child link="9g_servo_4B1"/>
</joint>

<joint name="Revolute_22" type="continuous">
  <origin xyz="6.9e-05 0.014275 -0.00799" rpy="0 0 0"/>
  <parent link="9g_servo_4B1"/>
  <child link="Hex_Leg_Joint_41"/>
  <axis xyz="-0.0 -1.0 -0.0"/>
  <dynamics damping="0.0" friction="1.0"/>
</joint>
<transmission name="Revolute_22_tran">
  <type>transmission_interface/SimpleTransmission</type>
  <joint name="Revolute_22">
    <hardwareInterface>PositionJointInterface</hardwareInterface>
  </joint>
  <actuator name="Revolute_22_actr">
    <hardwareInterface>PositionJointInterface</hardwareInterface>
    <mechanicalReduction>1</mechanicalReduction>
  </actuator>
</transmission>

<joint name="Rigid_23" type="fixed">
  <origin xyz="0.032177 -0.014481 0.013002" rpy="0 0 0"/>
  <parent link="Hex_Leg_Joint_41"/>
  <child link="9g_servo_4C1"/>
</joint>

<joint name="Revolute_24" type="continuous">
  <origin xyz="-0.000182 0.014025 -0.018987" rpy="0 0 0"/>
  <parent link="9g_servo_4C1"/>
  <child link="Hex_Leg_End_41"/>
  <axis xyz="0.0 -1.0 0.0"/>
  <dynamics damping="0.0" friction="1.0"/>
</joint>
<transmission name="Revolute_24_tran">
  <type>transmission_interface/SimpleTransmission</type>
  <joint name="Revolute_24">
    <hardwareInterface>PositionJointInterface</hardwareInterface>
  </joint>
  <actuator name="Revolute_24_actr">
    <hardwareInterface>PositionJointInterface</hardwareInterface>
    <mechanicalReduction>1</mechanicalReduction>
  </actuator>
</transmission>

<joint name="Rigid_25" type="fixed">
  <origin xyz="0.00925 -0.016021 0.01" rpy="0 0 0"/>
  <parent link="base_link"/>
  <child link="9g_servo_5A1"/>
</joint>

<joint name="Revolute_26" type="continuous">
  <origin xyz="0.009529 -0.016505 0.014275" rpy="0 0 0"/>
  <parent link="9g_servo_5A1"/>
  <child link="Hip_Mount_51"/>
  <axis xyz="-0.0 0.0 -1.0"/>
  <dynamics damping="0.0" friction="1.0"/>
</joint>
<transmission name="Revolute_26_tran">
  <type>transmission_interface/SimpleTransmission</type>
  <joint name="Revolute_26">
    <hardwareInterface>PositionJointInterface</hardwareInterface>
  </joint>
  <actuator name="Revolute_26_actr">
    <hardwareInterface>PositionJointInterface</hardwareInterface>
    <mechanicalReduction>1</mechanicalReduction>
  </actuator>
</transmission>

<joint name="Rigid_27" type="fixed">
  <origin xyz="0.016772 -0.02055 -0.002231" rpy="0 0 0"/>
  <parent link="Hip_Mount_51"/>
  <child link="9g_servo_5B1"/>
</joint>

<joint name="Revolute_28" type="continuous">
  <origin xyz="0.012397 0.007079 -0.00799" rpy="0 0 0"/>
  <parent link="9g_servo_5B1"/>
  <child link="Hex_Leg_Joint_51"/>
  <axis xyz="-0.866025 -0.5 -0.0"/>
  <dynamics damping="0.0" friction="1.0"/>
</joint>
<transmission name="Revolute_28_tran">
  <type>transmission_interface/SimpleTransmission</type>
  <joint name="Revolute_28">
    <hardwareInterface>PositionJointInterface</hardwareInterface>
  </joint>
  <actuator name="Revolute_28_actr">
    <hardwareInterface>PositionJointInterface</hardwareInterface>
    <mechanicalReduction>1</mechanicalReduction>
  </actuator>
</transmission>

<joint name="Rigid_29" type="fixed">
  <origin xyz="0.003548 -0.035108 0.013002" rpy="0 0 0"/>
  <parent link="Hex_Leg_Joint_51"/>
  <child link="9g_servo_5C1"/>
</joint>

<joint name="Revolute_30" type="continuous">
  <origin xyz="0.012055 0.007171 -0.018987" rpy="0 0 0"/>
  <parent link="9g_servo_5C1"/>
  <child link="Hex_Leg_End_51"/>
  <axis xyz="-0.866025 -0.5 -0.0"/>
  <dynamics damping="0.0" friction="1.0"/>
</joint>
<transmission name="Revolute_30_tran">
  <type>transmission_interface/SimpleTransmission</type>
  <joint name="Revolute_30">
    <hardwareInterface>PositionJointInterface</hardwareInterface>
  </joint>
  <actuator name="Revolute_30_actr">
    <hardwareInterface>PositionJointInterface</hardwareInterface>
    <mechanicalReduction>1</mechanicalReduction>
  </actuator>
</transmission>

<joint name="Rigid_31" type="fixed">
  <origin xyz="-0.00925 -0.016021 0.01" rpy="0 0 0"/>
  <parent link="base_link"/>
  <child link="9g_servo_6A1"/>
</joint>

<joint name="Revolute_32" type="continuous">
  <origin xyz="-0.009529 -0.016505 0.014275" rpy="0 0 0"/>
  <parent link="9g_servo_6A1"/>
  <child link="Hip_Mount_61"/>
  <axis xyz="0.0 -0.0 1.0"/>
  <dynamics damping="0.0" friction="1.0"/>
</joint>
<transmission name="Revolute_32_tran">
  <type>transmission_interface/SimpleTransmission</type>
  <joint name="Revolute_32">
    <hardwareInterface>PositionJointInterface</hardwareInterface>
  </joint>
  <actuator name="Revolute_32_actr">
    <hardwareInterface>PositionJointInterface</hardwareInterface>
    <mechanicalReduction>1</mechanicalReduction>
  </actuator>
</transmission>

<joint name="Rigid_33" type="fixed">
  <origin xyz="-0.00941 -0.0248 -0.002231" rpy="0 0 0"/>
  <parent link="Hip_Mount_61"/>
  <child link="9g_servo_6B1"/>
</joint>

<joint name="Revolute_34" type="continuous">
  <origin xyz="0.012328 -0.007196 -0.00799" rpy="0 0 0"/>
  <parent link="9g_servo_6B1"/>
  <child link="Hex_Leg_Joint_61"/>
  <axis xyz="0.866025 -0.5 0.0"/>
  <dynamics damping="0.0" friction="1.0"/>
</joint>
<transmission name="Revolute_34_tran">
  <type>transmission_interface/SimpleTransmission</type>
  <joint name="Revolute_34">
    <hardwareInterface>PositionJointInterface</hardwareInterface>
  </joint>
  <actuator name="Revolute_34_actr">
    <hardwareInterface>PositionJointInterface</hardwareInterface>
    <mechanicalReduction>1</mechanicalReduction>
  </actuator>
</transmission>

<joint name="Rigid_35" type="fixed">
  <origin xyz="-0.02863 -0.020627 0.013002" rpy="0 0 0"/>
  <parent link="Hex_Leg_Joint_61"/>
  <child link="9g_servo_6C1"/>
</joint>

<joint name="Revolute_36" type="continuous">
  <origin xyz="0.012237 -0.006855 -0.018987" rpy="0 0 0"/>
  <parent link="9g_servo_6C1"/>
  <child link="Hex_Leg_End_61"/>
  <axis xyz="-0.866025 0.5 0.0"/>
  <dynamics damping="0.0" friction="1.0"/>
</joint>
<transmission name="Revolute_36_tran">
  <type>transmission_interface/SimpleTransmission</type>
  <joint name="Revolute_36">
    <hardwareInterface>PositionJointInterface</hardwareInterface>
  </joint>
  <actuator name="Revolute_36_actr">
    <hardwareInterface>PositionJointInterface</hardwareInterface>
    <mechanicalReduction>1</mechanicalReduction>
  </actuator>
</transmission>

</robot>
